{"name": "test_criar_um_usuário_com_credenciais_válidas", "status": "failed", "statusDetails": {"message": "AssertionError: Erro: {\"code\":\"1204\",\"message\":\"User exists!\"}\nassert 406 == 201\n +  where 406 = <Response [406]>.status_code\n +    where <Response [406]> = pytest.response", "trace": "fixturefunc = <function verify_status_code at 0x1051cec00>, request = <FixtureRequest for <Function test_criar_um_usuário_com_credenciais_válidas>>, kwargs = {}\n\n    def call_fixture_func(\n        fixturefunc: _FixtureFunc[FixtureValue], request: FixtureRequest, kwargs\n    ) -> FixtureValue:\n        if is_generator(fixturefunc):\n            fixturefunc = cast(\n                Callable[..., Generator[FixtureValue, None, None]], fixturefunc\n            )\n            generator = fixturefunc(**kwargs)\n            try:\n                fixture_result = next(generator)\n            except StopIteration:\n                raise ValueError(f\"{request.fixturename} did not yield a value\") from None\n            finalizer = functools.partial(_teardown_yield_fixture, fixturefunc, generator)\n            request.addfinalizer(finalizer)\n        else:\n            fixturefunc = cast(Callable[..., FixtureValue], fixturefunc)\n>           fixture_result = fixturefunc(**kwargs)\n\n.venv/lib/python3.13/site-packages/_pytest/fixtures.py:898: \n_ _ _ _ _ _ _ _ _ _ _ _ _ _ _ _ _ _ _ _ _ _ _ _ _ _ _ _ _ _ _ _ _ _ _ _ _ _ _ _ _ _ _ _ _ _ _ _ _ _ _ _ _ _ _ _ _ _ _ _ _ _ _ _ _ _ _ _ _ _ _ _ _ _ _ _ _ _ _ _ _ _ _ _ _ _ _ _ _ _ _ _ _ _ _ _ _ _ _ _ _ _ _ _ _ _ _ _ _ _ _ _ _ _\n\n    @then(\"a API deve retornar um status 201\")\n    def verify_status_code():\n        \"\"\"Verifica se o status code é 201 (Created)\"\"\"\n>       assert pytest.response.status_code == 201, f\"Erro: {pytest.response.text}\"\nE       AssertionError: Erro: {\"code\":\"1204\",\"message\":\"User exists!\"}\nE       assert 406 == 201\nE        +  where 406 = <Response [406]>.status_code\nE        +    where <Response [406]> = pytest.response\n\ntests/api/test_create_user.py:36: AssertionError"}, "description": "/Users/daniloamedeiros/Desktop/project-challenge-qa-acc/features/api_create_user.feature: Criar um usuário com credenciais válidas", "start": 1739360863959, "stop": 1739360864759, "uuid": "fb2cbff1-8dca-4fb0-917a-8182540c3c76", "historyId": "a7574963e73b147341298284211deff8", "testCaseId": "a7574963e73b147341298284211deff8", "fullName": "tests.api.test_create_user#test_criar_um_usuário_com_credenciais_válidas", "labels": [{"name": "parentSuite", "value": "tests.api"}, {"name": "suite", "value": "test_create_user"}, {"name": "host", "value": "MacBook-Pro-de-Danilo.local"}, {"name": "thread", "value": "48487-MainThread"}, {"name": "framework", "value": "pytest"}, {"name": "language", "value": "cpython3"}, {"name": "package", "value": "tests.api.test_create_user"}]}